Workbook

Sheet A5 (5.8x8.3)
A1: Comix Wellspring A5 Size (5.8" x 8.3") - Discount Log
A2: Source: comixwellspring.com/products/comic-a5-size
A3: Cap: 75% off at 1000+ (confirmed at 1000/1500/2000/2500/5000). Change list price in B5 to recalc.
A5: List Price / Book: | B5: 4.07 | C5: (site base list: $3.60)
A7: Quantity | B7: Discount % | C7: List Price / Book | D7: Discounted Price / Book | E7: Subtotal (List) | F7: Total After Discount | G7: Total Savings | H7: Savings per Book | I7: Notes | K7: Analysis
A8: 1 | B8: 0 | C8: =$B$5 -> 4.07 | D8: =C8*(1-B8) -> 4.07 | E8: =A8*C8 -> 4.07 | F8: =A8*D8 -> 4.07 | G8: =E8-F8 -> 0 | H8: =C8-D8 -> 0 | I8: Site | K8: Max discount (cap) | L8: =MAX(B8:B20) -> 0.75
A9: 2 | B9: 0.091 | C9: =$B$5 -> 4.07 | D9: =C9*(1-B9) -> 3.69963 | E9: =A9*C9 -> 8.14 | F9: =A9*D9 -> 7.39926 | G9: =E9-F9 -> 0.74074 | H9: =C9-D9 -> 0.37037 | I9: Site | K9: Cheapest per book | L9: =MIN(D8:D20) -> 1.0175
A10: 5 | B10: 0.13 | C10: =$B$5 -> 4.07 | D10: =C10*(1-B10) -> 3.5409 | E10: =A10*C10 -> 20.35 | F10: =A10*D10 -> 17.7045 | G10: =E10-F10 -> 2.6455 | H10: =C10-D10 -> 0.5291 | I10: Site | K10: Total at max qty | L10: =F20 -> 1017.5
A11: 20 | B11: 0.28 | C11: =$B$5 -> 4.07 | D11: =C11*(1-B11) -> 2.9304 | E11: =A11*C11 -> 81.4 | F11: =A11*D11 -> 58.608 | G11: =E11-F11 -> 22.792 | H11: =C11-D11 -> 1.1396 | I11: Site | K11: Savings at max qty | L11: =G20 -> 3052.5
A12: 25 | B12: 0.357 | C12: =$B$5 -> 4.07 | D12: =C12*(1-B12) -> 2.61701 | E12: =A12*C12 -> 101.75 | F12: =A12*D12 -> 65.42525 | G12: =E12-F12 -> 36.32475 | H12: =C12-D12 -> 1.45299 | I12: Site
A13: 50 | B13: 0.433 | C13: =$B$5 -> 4.07 | D13: =C13*(1-B13) -> 2.30769 | E13: =A13*C13 -> 203.5 | F13: =A13*D13 -> 115.3845 | G13: =E13-F13 -> 88.1155 | H13: =C13-D13 -> 1.76231 | I13: Site
A14: 75 | B14: 0.469 | C14: =$B$5 -> 4.07 | D14: =C14*(1-B14) -> 2.16117 | E14: =A14*C14 -> 305.25 | F14: =A14*D14 -> 162.08775 | G14: =E14-F14 -> 143.16225 | H14: =C14-D14 -> 1.90883 | I14: Site
A15: 100 | B15: 0.541 | C15: =$B$5 -> 4.07 | D15: =C15*(1-B15) -> 1.86813 | E15: =A15*C15 -> 407 | F15: =A15*D15 -> 186.813 | G15: =E15-F15 -> 220.187 | H15: =C15-D15 -> 2.20187 | I15: Confirmed - screenshot
A16: 250 | B16: 0.619 | C16: =$B$5 -> 4.07 | D16: =C16*(1-B16) -> 1.55067 | E16: =A16*C16 -> 1017.5 | F16: =A16*D16 -> 387.6675 | G16: =E16-F16 -> 629.8325 | H16: =C16-D16 -> 2.51933 | I16: Site
A17: 300 | B17: 0.66 | C17: =$B$5 -> 4.07 | D17: =C17*(1-B17) -> 1.3838 | E17: =A17*C17 -> 1221 | F17: =A17*D17 -> 415.14 | G17: =E17-F17 -> 805.86 | H17: =C17-D17 -> 2.6862 | I17: Site
A18: 500 | B18: 0.688 | C18: =$B$5 -> 4.07 | D18: =C18*(1-B18) -> 1.26984 | E18: =A18*C18 -> 2035 | F18: =A18*D18 -> 634.92 | G18: =E18-F18 -> 1400.08 | H18: =C18-D18 -> 2.80016 | I18: Site
A19: 750 | B19: 0.711 | C19: =$B$5 -> 4.07 | D19: =C19*(1-B19) -> 1.17623 | E19: =A19*C19 -> 3052.5 | F19: =A19*D19 -> 882.1725 | G19: =E19-F19 -> 2170.3275 | H19: =C19-D19 -> 2.89377 | I19: Site
A20: 1000 | B20: 0.75 | C20: =$B$5 -> 4.07 | D20: =C20*(1-B20) -> 1.0175 | E20: =A20*C20 -> 4070 | F20: =A20*D20 -> 1017.5 | G20: =E20-F20 -> 3052.5 | H20: =C20-D20 -> 3.0525 | I20: Site - cap reached
A24: Cover Upgrades - Per-Book Add-On (discounted along with base)
A25: Pick a cover and a quantity below; calculator shows final per-book and total. Upgrade price adds to list, then quantity discount applies to the combined amount.
A27: Cover Option | B27: Upgrade $/book | C27: Paper Stock
A28: Self Cover | B28: 0 | C28: Same as Interior Selection
A29: Standard Matte | B29: 0.51 | C29: 80lb Uncoated Cover
A30: Standard Semi-Gloss | B30: 0.51 | C30: 80lb Silk Cover
A31: Standard Gloss | B31: 0.47 | C31: 80lb Coated Cover
A32: Deluxe Gloss | B32: 0.51 | C32: 100lb Gloss Cover
A33: Premium Gloss | B33: 0.6 | C33: 12pt Gloss Card Stock
A34: Holo-Chrome | B34: 6.67 | C34: 12pt Holo-Chrome Card Stock
A37: Lamination Embellishment
A38: Lamination Style | B38: $/book
A39: None | B39: 0
A40: Gloss | B40: 0.71
A41: Matte | B41: 0.77
A44: UV Embellishment
A45: UV Style | B45: $/book
A46: None | B46: 0
A47: UV Coat | B47: 0.14
A48: Spot UV | B48: 0.77
A51: Foil Cover Embellishment
A52: Foil Color | B52: $/book
...

Sheet Standard (6.625x10.25)
A1: Comix Wellspring Standard Size (6.625" x 10.25") - Discount Log
A2: Source: comixwellspring.com/products/comic-standard-size
A3: Max published discount: 66.9% at 1000. Change list price in B5 to recalc.
A5: List Price / Book: | B5: 5.36 | C5: (site base list: $5.36)
A7: Quantity | B7: Discount % | C7: List Price / Book | D7: Discounted Price / Book | E7: Subtotal (List) | F7: Total After Discount | G7: Total Savings | H7: Savings per Book | I7: Notes | K7: Analysis
A8: 1 | B8: 0 | C8: =$B$5 -> 5.36 | D8: =C8*(1-B8) -> 5.36 | E8: =A8*C8 -> 5.36 | F8: =A8*D8 -> 5.36 | G8: =E8-F8 -> 0 | H8: =C8-D8 -> 0 | I8: Site | K8: Max discount (cap) | L8: =MAX(B8:B20) -> 0.669
A9: 2 | B9: 0.115 | C9: =$B$5 -> 5.36 | D9: =C9*(1-B9) -> 4.7436 | E9: =A9*C9 -> 10.72 | F9: =A9*D9 -> 9.4872 | G9: =E9-F9 -> 1.2328 | H9: =C9-D9 -> 0.6164 | I9: Site | K9: Cheapest per book | L9: =MIN(D8:D20) -> 1.77416
A10: 5 | B10: 0.138 | C10: =$B$5 -> 5.36 | D10: =C10*(1-B10) -> 4.62032 | E10: =A10*C10 -> 26.8 | F10: =A10*D10 -> 23.1016 | G10: =E10-F10 -> 3.6984 | H10: =C10-D10 -> 0.73968 | I10: Site | K10: Total at max qty | L10: =F20 -> 1774.16
A11: 20 | B11: 0.339 | C11: =$B$5 -> 5.36 | D11: =C11*(1-B11) -> 3.54296 | E11: =A11*C11 -> 107.2 | F11: =A11*D11 -> 70.8592 | G11: =E11-F11 -> 36.3408 | H11: =C11-D11 -> 1.81704 | I11: Site | K11: Savings at max qty | L11: =G20 -> 3585.84
A12: 25 | B12: 0.366 | C12: =$B$5 -> 5.36 | D12: =C12*(1-B12) -> 3.39824 | E12: =A12*C12 -> 134 | F12: =A12*D12 -> 84.956 | G12: =E12-F12 -> 49.044 | H12: =C12-D12 -> 1.96176 | I12: Site
A13: 50 | B13: 0.436 | C13: =$B$5 -> 5.36 | D13: =C13*(1-B13) -> 3.02304 | E13: =A13*C13 -> 268 | F13: =A13*D13 -> 151.152 | G13: =E13-F13 -> 116.848 | H13: =C13-D13 -> 2.33696 | I13: Site
A14: 75 | B14: 0.467 | C14: =$B$5 -> 5.36 | D14: =C14*(1-B14) -> 2.85688 | E14: =A14*C14 -> 402 | F14: =A14*D14 -> 214.266 | G14: =E14-F14 -> 187.734 | H14: =C14-D14 -> 2.50312 | I14: Site
A15: 100 | B15: 0.511 | C15: =$B$5 -> 5.36 | D15: =C15*(1-B15) -> 2.62104 | E15: =A15*C15 -> 536 | F15: =A15*D15 -> 262.104 | G15: =E15-F15 -> 273.896 | H15: =C15-D15 -> 2.73896 | I15: Site
A16: 250 | B16: 0.555 | C16: =$B$5 -> 5.36 | D16: =C16*(1-B16) -> 2.3852 | E16: =A16*C16 -> 1340 | F16: =A16*D16 -> 596.3 | G16: =E16-F16 -> 743.7 | H16: =C16-D16 -> 2.9748 | I16: Site
A17: 300 | B17: 0.569 | C17: =$B$5 -> 5.36 | D17: =C17*(1-B17) -> 2.31016 | E17: =A17*C17 -> 1608 | F17: =A17*D17 -> 693.048 | G17: =E17-F17 -> 914.952 | H17: =C17-D17 -> 3.04984 | I17: Site
A18: 500 | B18: 0.598 | C18: =$B$5 -> 5.36 | D18: =C18*(1-B18) -> 2.15472 | E18: =A18*C18 -> 2680 | F18: =A18*D18 -> 1077.36 | G18: =E18-F18 -> 1602.64 | H18: =C18-D18 -> 3.20528 | I18: Site
A19: 750 | B19: 0.621 | C19: =$B$5 -> 5.36 | D19: =C19*(1-B19) -> 2.03144 | E19: =A19*C19 -> 4020 | F19: =A19*D19 -> 1523.58 | G19: =E19-F19 -> 2496.42 | H19: =C19-D19 -> 3.32856 | I19: Site
A20: 1000 | B20: 0.669 | C20: =$B$5 -> 5.36 | D20: =C20*(1-B20) -> 1.77416 | E20: =A20*C20 -> 5360 | F20: =A20*D20 -> 1774.16 | G20: =E20-F20 -> 3585.84 | H20: =C20-D20 -> 3.58584 | I20: Site
A23: Cover Upgrades - Per-Book Add-On (discounted along with base)
A24: Pick a cover and a quantity in the calculator below. Upgrade price adds to list, then quantity discount applies to the combined amount.
A26: Cover Option | B26: Upgrade $/book | C26: Paper Stock
A27: Self Cover | B27: 0 | C27: Same as Interior Selection
A28: Standard Matte | B28: 0.51 | C28: 80lb Uncoated Cover
A29: Standard Semi-Gloss | B29: 0.51 | C29: 80lb Silk Cover
A30: Standard Gloss | B30: 0.47 | C30: 80lb Coated Cover
A31: Deluxe Gloss | B31: 0.51 | C31: 100lb Gloss Cover
A32: Premium Gloss | B32: 0.6 | C32: 12pt Gloss Card Stock
A33: Holo-Chrome | B33: 6.67 | C33: 12pt Holo-Chrome Card Stock
A36: Lamination Embellishment
A37: Lamination Style | B37: $/book
A38: None | B38: 0
A39: Gloss | B39: 0.71
A40: Matte | B40: 0.77
A43: UV Embellishment
A44: UV Style | B44: $/book
A45: None | B45: 0
A46: UV Coat | B46: 0.14
A47: Spot UV | B47: 0.77
A50: Foil Cover Embellishment
A51: Foil Color | B51: $/book
...

Sheet Magazine (8x10.5)
A1: Comix Wellspring Magazine Size (8" x 10.5") - Discount Log
A2: Source: comixwellspring.com/products/comic-magazine-size
A3: Max published discount: 66.0% at 1000. Change list price in B5 to recalc.
A5: List Price / Book: | B5: 5.59 | C5: (site base list: $5.59)
A7: Quantity | B7: Discount % | C7: List Price / Book | D7: Discounted Price / Book | E7: Subtotal (List) | F7: Total After Discount | G7: Total Savings | H7: Savings per Book | I7: Notes | K7: Analysis
A8: 1 | B8: 0 | C8: =$B$5 -> 5.59 | D8: =C8*(1-B8) -> 5.59 | E8: =A8*C8 -> 5.59 | F8: =A8*D8 -> 5.59 | G8: =E8-F8 -> 0 | H8: =C8-D8 -> 0 | I8: Site | K8: Max discount (cap) | L8: =MAX(B8:B20) -> 0.66
A9: 2 | B9: 0.056 | C9: =$B$5 -> 5.59 | D9: =C9*(1-B9) -> 5.27696 | E9: =A9*C9 -> 11.18 | F9: =A9*D9 -> 10.55392 | G9: =E9-F9 -> 0.62608 | H9: =C9-D9 -> 0.31304 | I9: Site | K9: Cheapest per book | L9: =MIN(D8:D20) -> 1.9006
A10: 5 | B10: 0.081 | C10: =$B$5 -> 5.59 | D10: =C10*(1-B10) -> 5.13721 | E10: =A10*C10 -> 27.95 | F10: =A10*D10 -> 25.68605 | G10: =E10-F10 -> 2.26395 | H10: =C10-D10 -> 0.45279 | I10: Site | K10: Total at max qty | L10: =F20 -> 1900.6
A11: 20 | B11: 0.215 | C11: =$B$5 -> 5.59 | D11: =C11*(1-B11) -> 4.38815 | E11: =A11*C11 -> 111.8 | F11: =A11*D11 -> 87.763 | G11: =E11-F11 -> 24.037 | H11: =C11-D11 -> 1.20185 | I11: Site | K11: Savings at max qty | L11: =G20 -> 3689.4
A12: 25 | B12: 0.271 | C12: =$B$5 -> 5.59 | D12: =C12*(1-B12) -> 4.07511 | E12: =A12*C12 -> 139.75 | F12: =A12*D12 -> 101.87775 | G12: =E12-F12 -> 37.87225 | H12: =C12-D12 -> 1.51489 | I12: Site
A13: 50 | B13: 0.343 | C13: =$B$5 -> 5.59 | D13: =C13*(1-B13) -> 3.67263 | E13: =A13*C13 -> 279.5 | F13: =A13*D13 -> 183.6315 | G13: =E13-F13 -> 95.8685 | H13: =C13-D13 -> 1.91737 | I13: Site
A14: 75 | B14: 0.372 | C14: =$B$5 -> 5.59 | D14: =C14*(1-B14) -> 3.51052 | E14: =A14*C14 -> 419.25 | F14: =A14*D14 -> 263.289 | G14: =E14-F14 -> 155.961 | H14: =C14-D14 -> 2.07948 | I14: Site
A15: 100 | B15: 0.433 | C15: =$B$5 -> 5.59 | D15: =C15*(1-B15) -> 3.16953 | E15: =A15*C15 -> 559 | F15: =A15*D15 -> 316.953 | G15: =E15-F15 -> 242.047 | H15: =C15-D15 -> 2.42047 | I15: Site
A16: 250 | B16: 0.514 | C16: =$B$5 -> 5.59 | D16: =C16*(1-B16) -> 2.71674 | E16: =A16*C16 -> 1397.5 | F16: =A16*D16 -> 679.185 | G16: =E16-F16 -> 718.315 | H16: =C16-D16 -> 2.87326 | I16: Site
A17: 300 | B17: 0.554 | C17: =$B$5 -> 5.59 | D17: =C17*(1-B17) -> 2.49314 | E17: =A17*C17 -> 1677 | F17: =A17*D17 -> 747.942 | G17: =E17-F17 -> 929.058 | H17: =C17-D17 -> 3.09686 | I17: Site
A18: 500 | B18: 0.586 | C18: =$B$5 -> 5.59 | D18: =C18*(1-B18) -> 2.31426 | E18: =A18*C18 -> 2795 | F18: =A18*D18 -> 1157.13 | G18: =E18-F18 -> 1637.87 | H18: =C18-D18 -> 3.27574 | I18: Site
A19: 750 | B19: 0.61 | C19: =$B$5 -> 5.59 | D19: =C19*(1-B19) -> 2.1801 | E19: =A19*C19 -> 4192.5 | F19: =A19*D19 -> 1635.075 | G19: =E19-F19 -> 2557.425 | H19: =C19-D19 -> 3.4099 | I19: Site
A20: 1000 | B20: 0.66 | C20: =$B$5 -> 5.59 | D20: =C20*(1-B20) -> 1.9006 | E20: =A20*C20 -> 5590 | F20: =A20*D20 -> 1900.6 | G20: =E20-F20 -> 3689.4 | H20: =C20-D20 -> 3.6894 | I20: Site
A23: Cover Upgrades - Per-Book Add-On (discounted along with base)
A24: Pick a cover and a quantity in the calculator below. Upgrade price adds to list, then quantity discount applies to the combined amount.
A26: Cover Option | B26: Upgrade $/book | C26: Paper Stock
A27: Self Cover | B27: 0 | C27: Same as Interior Selection
A28: Standard Matte | B28: 0.51 | C28: 80lb Uncoated Cover
A29: Standard Semi-Gloss | B29: 0.51 | C29: 80lb Silk Cover
A30: Standard Gloss | B30: 0.47 | C30: 80lb Coated Cover
A31: Deluxe Gloss | B31: 0.51 | C31: 100lb Gloss Cover
A32: Premium Gloss | B32: 0.6 | C32: 12pt Gloss Card Stock
A33: Holo-Chrome | B33: 6.67 | C33: 12pt Holo-Chrome Card Stock
A36: Lamination Embellishment
A37: Lamination Style | B37: $/book
A38: None | B38: 0
A39: Gloss | B39: 0.71
A40: Matte | B40: 0.77
A43: UV Embellishment
A44: UV Style | B44: $/book
A45: None | B45: 0
A46: UV Coat | B46: 0.14
A47: Spot UV | B47: 0.77
A50: Foil Cover Embellishment
A51: Foil Color | B51: $/book
...

Sheet Letter (8.5x11)
A1: Comix Wellspring Letter Size (8.5" x 11") - Discount Log
A2: Source: comixwellspring.com/products/comics-letter-size
A3: Max published discount: 66.0% at 1000. Same discount curve as Magazine. Change list price in B5 to recalc.
A5: List Price / Book: | B5: 5.59 | C5: (site base list: $5.59)
A7: Quantity | B7: Discount % | C7: List Price / Book | D7: Discounted Price / Book | E7: Subtotal (List) | F7: Total After Discount | G7: Total Savings | H7: Savings per Book | I7: Notes | K7: Analysis
A8: 1 | B8: 0 | C8: =$B$5 -> 5.59 | D8: =C8*(1-B8) -> 5.59 | E8: =A8*C8 -> 5.59 | F8: =A8*D8 -> 5.59 | G8: =E8-F8 -> 0 | H8: =C8-D8 -> 0 | I8: Site | K8: Max discount (cap) | L8: =MAX(B8:B20) -> 0.66
A9: 2 | B9: 0.056 | C9: =$B$5 -> 5.59 | D9: =C9*(1-B9) -> 5.27696 | E9: =A9*C9 -> 11.18 | F9: =A9*D9 -> 10.55392 | G9: =E9-F9 -> 0.62608 | H9: =C9-D9 -> 0.31304 | I9: Site | K9: Cheapest per book | L9: =MIN(D8:D20) -> 1.9006
A10: 5 | B10: 0.081 | C10: =$B$5 -> 5.59 | D10: =C10*(1-B10) -> 5.13721 | E10: =A10*C10 -> 27.95 | F10: =A10*D10 -> 25.68605 | G10: =E10-F10 -> 2.26395 | H10: =C10-D10 -> 0.45279 | I10: Site | K10: Total at max qty | L10: =F20 -> 1900.6
A11: 20 | B11: 0.215 | C11: =$B$5 -> 5.59 | D11: =C11*(1-B11) -> 4.38815 | E11: =A11*C11 -> 111.8 | F11: =A11*D11 -> 87.763 | G11: =E11-F11 -> 24.037 | H11: =C11-D11 -> 1.20185 | I11: Site | K11: Savings at max qty | L11: =G20 -> 3689.4
A12: 25 | B12: 0.271 | C12: =$B$5 -> 5.59 | D12: =C12*(1-B12) -> 4.07511 | E12: =A12*C12 -> 139.75 | F12: =A12*D12 -> 101.87775 | G12: =E12-F12 -> 37.87225 | H12: =C12-D12 -> 1.51489 | I12: Site
A13: 50 | B13: 0.343 | C13: =$B$5 -> 5.59 | D13: =C13*(1-B13) -> 3.67263 | E13: =A13*C13 -> 279.5 | F13: =A13*D13 -> 183.6315 | G13: =E13-F13 -> 95.8685 | H13: =C13-D13 -> 1.91737 | I13: Site
A14: 75 | B14: 0.372 | C14: =$B$5 -> 5.59 | D14: =C14*(1-B14) -> 3.51052 | E14: =A14*C14 -> 419.25 | F14: =A14*D14 -> 263.289 | G14: =E14-F14 -> 155.961 | H14: =C14-D14 -> 2.07948 | I14: Site
A15: 100 | B15: 0.433 | C15: =$B$5 -> 5.59 | D15: =C15*(1-B15) -> 3.16953 | E15: =A15*C15 -> 559 | F15: =A15*D15 -> 316.953 | G15: =E15-F15 -> 242.047 | H15: =C15-D15 -> 2.42047 | I15: Site
A16: 250 | B16: 0.514 | C16: =$B$5 -> 5.59 | D16: =C16*(1-B16) -> 2.71674 | E16: =A16*C16 -> 1397.5 | F16: =A16*D16 -> 679.185 | G16: =E16-F16 -> 718.315 | H16: =C16-D16 -> 2.87326 | I16: Site
A17: 300 | B17: 0.554 | C17: =$B$5 -> 5.59 | D17: =C17*(1-B17) -> 2.49314 | E17: =A17*C17 -> 1677 | F17: =A17*D17 -> 747.942 | G17: =E17-F17 -> 929.058 | H17: =C17-D17 -> 3.09686 | I17: Site
A18: 500 | B18: 0.586 | C18: =$B$5 -> 5.59 | D18: =C18*(1-B18) -> 2.31426 | E18: =A18*C18 -> 2795 | F18: =A18*D18 -> 1157.13 | G18: =E18-F18 -> 1637.87 | H18: =C18-D18 -> 3.27574 | I18: Site
A19: 750 | B19: 0.61 | C19: =$B$5 -> 5.59 | D19: =C19*(1-B19) -> 2.1801 | E19: =A19*C19 -> 4192.5 | F19: =A19*D19 -> 1635.075 | G19: =E19-F19 -> 2557.425 | H19: =C19-D19 -> 3.4099 | I19: Site
A20: 1000 | B20: 0.66 | C20: =$B$5 -> 5.59 | D20: =C20*(1-B20) -> 1.9006 | E20: =A20*C20 -> 5590 | F20: =A20*D20 -> 1900.6 | G20: =E20-F20 -> 3689.4 | H20: =C20-D20 -> 3.6894 | I20: Site
A23: Pages - Grayscale Uncoated | D23: Pages - Grayscale Semi Gloss | G23: Pages - Grayscale Gloss
A24: 8 pages baseline. Each +4 pages adds $0.17. | D24: 8 pages baseline. Each +4 pages adds $0.18. | G24: 8 pages baseline. Each +4 pages adds $0.18.
A26: Interior Pages | B26: Upgrade $/book | D26: Interior Pages | E26: Upgrade $/book | G26: Interior Pages | H26: Upgrade $/book
A27: 8 | B27: 0 | D27: 8 | E27: 0 | G27: 8 | H27: 0
A28: 12 | B28: 0.17 | D28: 12 | E28: 0.18 | G28: 12 | H28: 0.18
A29: 16 | B29: 0.34 | D29: 16 | E29: 0.36 | G29: 16 | H29: 0.36
A30: 20 | B30: 0.51 | D30: 20 | E30: 0.54 | G30: 20 | H30: 0.54
A31: 24 | B31: 0.68 | D31: 24 | E31: 0.72 | G31: 24 | H31: 0.72
A32: 28 | B32: 0.85 | D32: 28 | E32: 0.9 | G32: 28 | H32: 0.9
A33: 32 | B33: 1.02 | D33: 32 | E33: 1.08 | G33: 32 | H33: 1.08
A34: 36 | B34: 1.19 | D34: 36 | E34: 1.26 | G34: 36 | H34: 1.26
A35: 40 | B35: 1.36 | D35: 40 | E35: 1.44 | G35: 40 | H35: 1.44
A36: 44 | B36: 1.53 | D36: 44 | E36: 1.62 | G36: 44 | H36: 1.62
A37: 48 | B37: 1.7 | D37: 48 | E37: 1.8 | G37: 48 | H37: 1.8
A38: 52 | B38: 1.87 | D38: 52 | E38: 1.98 | G38: 52 | H38: 1.98
A41: Pages - Full Color Uncoated | D41: Pages - Full Color Semi Gloss | G41: Pages - Full Color Gloss
A42: 8 pages baseline. Each +4 pages adds $0.26. | D42: 8 pages baseline. Each +4 pages adds $0.28. | G42: 8 pages baseline. Each +4 pages adds $0.28.
A44: Interior Pages | B44: Upgrade $/book | D44: Interior Pages | E44: Upgrade $/book | G44: Interior Pages | H44: Upgrade $/book
A45: 8 | B45: 0 | D45: 8 | E45: 0 | G45: 8 | H45: 0
A46: 12 | B46: 0.26 | D46: 12 | E46: 0.28 | G46: 12 | H46: 0.28
A47: 16 | B47: 0.52 | D47: 16 | E47: 0.56 | G47: 16 | H47: 0.56
A48: 20 | B48: 0.78 | D48: 20 | E48: 0.84 | G48: 20 | H48: 0.84
...

Sheet Comparison
A1: All Sizes - Side by Side
A2: Pulls live from each size tab - edit list prices there to see impact here. Green = per-book $, black = discount %.
A4: Qty | B4: A5 | E4: Standard | H4: Magazine | K4: Letter
B5: Disc % | C5: $/book | D5: Total | E5: Disc % | F5: $/book | G5: Total | H5: Disc % | I5: $/book | J5: Total | K5: Disc % | L5: $/book | M5: Total
A6: 1 | B6: ='A5 (5.8x8.3)'!B8 -> 0 | C6: ='A5 (5.8x8.3)'!D8 -> 4.07 | D6: =A6*C6 -> 4.07 | E6: ='Standard (6.625x10.25)'!B8 -> 0 | F6: ='Standard (6.625x10.25)'!D8 -> 5.36 | G6: =A6*F6 -> 5.36 | H6: ='Magazine (8x10.5)'!B8 -> 0 | I6: ='Magazine (8x10.5)'!D8 -> 5.59 | J6: =A6*I6 -> 5.59 | K6: ='Letter (8.5x11)'!B8 -> 0 | L6: ='Letter (8.5x11)'!D8 -> 5.59 | M6: =A6*L6 -> 5.59
A7: 2 | B7: ='A5 (5.8x8.3)'!B9 -> 0.091 | C7: ='A5 (5.8x8.3)'!D9 -> 3.69963 | D7: =A7*C7 -> 7.39926 | E7: ='Standard (6.625x10.25)'!B9 -> 0.115 | F7: ='Standard (6.625x10.25)'!D9 -> 4.7436 | G7: =A7*F7 -> 9.4872 | H7: ='Magazine (8x10.5)'!B9 -> 0.056 | I7: ='Magazine (8x10.5)'!D9 -> 5.27696 | J7: =A7*I7 -> 10.55392 | K7: ='Letter (8.5x11)'!B9 -> 0.056 | L7: ='Letter (8.5x11)'!D9 -> 5.27696 | M7: =A7*L7 -> 10.55392
A8: 5 | B8: ='A5 (5.8x8.3)'!B10 -> 0.13 | C8: ='A5 (5.8x8.3)'!D10 -> 3.5409 | D8: =A8*C8 -> 17.7045 | E8: ='Standard (6.625x10.25)'!B10 -> 0.138 | F8: ='Standard (6.625x10.25)'!D10 -> 4.62032 | G8: =A8*F8 -> 23.1016 | H8: ='Magazine (8x10.5)'!B10 -> 0.081 | I8: ='Magazine (8x10.5)'!D10 -> 5.13721 | J8: =A8*I8 -> 25.68605 | K8: ='Letter (8.5x11)'!B10 -> 0.081 | L8: ='Letter (8.5x11)'!D10 -> 5.13721 | M8: =A8*L8 -> 25.68605
A9: 20 | B9: ='A5 (5.8x8.3)'!B11 -> 0.28 | C9: ='A5 (5.8x8.3)'!D11 -> 2.9304 | D9: =A9*C9 -> 58.608 | E9: ='Standard (6.625x10.25)'!B11 -> 0.339 | F9: ='Standard (6.625x10.25)'!D11 -> 3.54296 | G9: =A9*F9 -> 70.8592 | H9: ='Magazine (8x10.5)'!B11 -> 0.215 | I9: ='Magazine (8x10.5)'!D11 -> 4.38815 | J9: =A9*I9 -> 87.763 | K9: ='Letter (8.5x11)'!B11 -> 0.215 | L9: ='Letter (8.5x11)'!D11 -> 4.38815 | M9: =A9*L9 -> 87.763
A10: 25 | B10: ='A5 (5.8x8.3)'!B12 -> 0.357 | C10: ='A5 (5.8x8.3)'!D12 -> 2.61701 | D10: =A10*C10 -> 65.42525 | E10: ='Standard (6.625x10.25)'!B12 -> 0.366 | F10: ='Standard (6.625x10.25)'!D12 -> 3.39824 | G10: =A10*F10 -> 84.956 | H10: ='Magazine (8x10.5)'!B12 -> 0.271 | I10: ='Magazine (8x10.5)'!D12 -> 4.07511 | J10: =A10*I10 -> 101.87775 | K10: ='Letter (8.5x11)'!B12 -> 0.271 | L10: ='Letter (8.5x11)'!D12 -> 4.07511 | M10: =A10*L10 -> 101.87775
A11: 50 | B11: ='A5 (5.8x8.3)'!B13 -> 0.433 | C11: ='A5 (5.8x8.3)'!D13 -> 2.30769 | D11: =A11*C11 -> 115.3845 | E11: ='Standard (6.625x10.25)'!B13 -> 0.436 | F11: ='Standard (6.625x10.25)'!D13 -> 3.02304 | G11: =A11*F11 -> 151.152 | H11: ='Magazine (8x10.5)'!B13 -> 0.343 | I11: ='Magazine (8x10.5)'!D13 -> 3.67263 | J11: =A11*I11 -> 183.6315 | K11: ='Letter (8.5x11)'!B13 -> 0.343 | L11: ='Letter (8.5x11)'!D13 -> 3.67263 | M11: =A11*L11 -> 183.6315
A12: 75 | B12: ='A5 (5.8x8.3)'!B14 -> 0.469 | C12: ='A5 (5.8x8.3)'!D14 -> 2.16117 | D12: =A12*C12 -> 162.08775 | E12: ='Standard (6.625x10.25)'!B14 -> 0.467 | F12: ='Standard (6.625x10.25)'!D14 -> 2.85688 | G12: =A12*F12 -> 214.266 | H12: ='Magazine (8x10.5)'!B14 -> 0.372 | I12: ='Magazine (8x10.5)'!D14 -> 3.51052 | J12: =A12*I12 -> 263.289 | K12: ='Letter (8.5x11)'!B14 -> 0.372 | L12: ='Letter (8.5x11)'!D14 -> 3.51052 | M12: =A12*L12 -> 263.289
A13: 100 | B13: ='A5 (5.8x8.3)'!B15 -> 0.541 | C13: ='A5 (5.8x8.3)'!D15 -> 1.86813 | D13: =A13*C13 -> 186.813 | E13: ='Standard (6.625x10.25)'!B15 -> 0.511 | F13: ='Standard (6.625x10.25)'!D15 -> 2.62104 | G13: =A13*F13 -> 262.104 | H13: ='Magazine (8x10.5)'!B15 -> 0.433 | I13: ='Magazine (8x10.5)'!D15 -> 3.16953 | J13: =A13*I13 -> 316.953 | K13: ='Letter (8.5x11)'!B15 -> 0.433 | L13: ='Letter (8.5x11)'!D15 -> 3.16953 | M13: =A13*L13 -> 316.953
A14: 250 | B14: ='A5 (5.8x8.3)'!B16 -> 0.619 | C14: ='A5 (5.8x8.3)'!D16 -> 1.55067 | D14: =A14*C14 -> 387.6675 | E14: ='Standard (6.625x10.25)'!B16 -> 0.555 | F14: ='Standard (6.625x10.25)'!D16 -> 2.3852 | G14: =A14*F14 -> 596.3 | H14: ='Magazine (8x10.5)'!B16 -> 0.514 | I14: ='Magazine (8x10.5)'!D16 -> 2.71674 | J14: =A14*I14 -> 679.185 | K14: ='Letter (8.5x11)'!B16 -> 0.514 | L14: ='Letter (8.5x11)'!D16 -> 2.71674 | M14: =A14*L14 -> 679.185
A15: 300 | B15: ='A5 (5.8x8.3)'!B17 -> 0.66 | C15: ='A5 (5.8x8.3)'!D17 -> 1.3838 | D15: =A15*C15 -> 415.14 | E15: ='Standard (6.625x10.25)'!B17 -> 0.569 | F15: ='Standard (6.625x10.25)'!D17 -> 2.31016 | G15: =A15*F15 -> 693.048 | H15: ='Magazine (8x10.5)'!B17 -> 0.554 | I15: ='Magazine (8x10.5)'!D17 -> 2.49314 | J15: =A15*I15 -> 747.942 | K15: ='Letter (8.5x11)'!B17 -> 0.554 | L15: ='Letter (8.5x11)'!D17 -> 2.49314 | M15: =A15*L15 -> 747.942
A16: 500 | B16: ='A5 (5.8x8.3)'!B18 -> 0.688 | C16: ='A5 (5.8x8.3)'!D18 -> 1.26984 | D16: =A16*C16 -> 634.92 | E16: ='Standard (6.625x10.25)'!B18 -> 0.598 | F16: ='Standard (6.625x10.25)'!D18 -> 2.15472 | G16: =A16*F16 -> 1077.36 | H16: ='Magazine (8x10.5)'!B18 -> 0.586 | I16: ='Magazine (8x10.5)'!D18 -> 2.31426 | J16: =A16*I16 -> 1157.13 | K16: ='Letter (8.5x11)'!B18 -> 0.586 | L16: ='Letter (8.5x11)'!D18 -> 2.31426 | M16: =A16*L16 -> 1157.13
A17: 750 | B17: ='A5 (5.8x8.3)'!B19 -> 0.711 | C17: ='A5 (5.8x8.3)'!D19 -> 1.17623 | D17: =A17*C17 -> 882.1725 | E17: ='Standard (6.625x10.25)'!B19 -> 0.621 | F17: ='Standard (6.625x10.25)'!D19 -> 2.03144 | G17: =A17*F17 -> 1523.58 | H17: ='Magazine (8x10.5)'!B19 -> 0.61 | I17: ='Magazine (8x10.5)'!D19 -> 2.1801 | J17: =A17*I17 -> 1635.075 | K17: ='Letter (8.5x11)'!B19 -> 0.61 | L17: ='Letter (8.5x11)'!D19 -> 2.1801 | M17: =A17*L17 -> 1635.075
A18: 1000 | B18: ='A5 (5.8x8.3)'!B20 -> 0.75 | C18: ='A5 (5.8x8.3)'!D20 -> 1.0175 | D18: =A18*C18 -> 1017.5 | E18: ='Standard (6.625x10.25)'!B20 -> 0.669 | F18: ='Standard (6.625x10.25)'!D20 -> 1.77416 | G18: =A18*F18 -> 1774.16 | H18: ='Magazine (8x10.5)'!B20 -> 0.66 | I18: ='Magazine (8x10.5)'!D20 -> 1.9006 | J18: =A18*I18 -> 1900.6 | K18: ='Letter (8.5x11)'!B20 -> 0.66 | L18: ='Letter (8.5x11)'!D20 -> 1.9006 | M18: =A18*L18 -> 1900.6
A21: Observations
A22: - Magazine and Letter share the SAME discount curve and base price ($5.59) - they're priced identically.
A23: - A5 has the best discount cap (75%) and the lowest base price ($3.60) - cheapest by far at scale.
A24: - Standard falls between A5 and Magazine/Letter on discounts (66.9% max).
A25: - Quantity break-points are identical across all four products: 1, 2, 5, 20, 25, 50, 75, 100, 250, 300, 500, 750, 1000.
A26: - At 1000 copies: A5 = $1.02/book, Standard = $1.77/book, Magazine/Letter = $1.90/book.
